<?xml version="1.0" encoding="utf-8"?>
<!-- This URDF was automatically created by SolidWorks to URDF Exporter! Originally created by Stephen Brawner (brawner@gmail.com) 
     Commit Version: 1.6.0-4-g7f85cfe  Build Version: 1.6.7995.38578
     For more information, please see http://wiki.ros.org/sw_urdf_exporter -->
<robot
  name="Chassis.SLDASM">
  <link
    name="base_link">
    <inertial>
      <origin
        xyz="-0.34279 0.13172 -0.0021816"
        rpy="0 0 0" />
      <mass
        value="1.4987" />
      <inertia
        ixx="0.029347"
        ixy="-1.1568E-05"
        ixz="-1.6569E-07"
        iyy="0.035721"
        iyz="1.4001E-07"
        izz="0.020508" />
    </inertial>
    <visual>
      <origin
        xyz="0 0 0"
        rpy="0 0 0" />
      <geometry>
        <mesh
          filename="package://Chassis.SLDASM/meshes/base_link.STL" />
      </geometry>
      <material
        name="">
        <color
          rgba="0.75294 0.75294 0.75294 1" />
      </material>
    </visual>
    <collision>
      <origin
        xyz="0 0 0"
        rpy="0 0 0" />
      <geometry>
        <mesh
          filename="package://Chassis.SLDASM/meshes/base_link.STL" />
      </geometry>
    </collision>
  </link>
  <link
    name="Right Rocker">
    <inertial>
      <origin
        xyz="-0.0436 -0.043913 -0.11068"
        rpy="0 0 0" />
      <mass
        value="1.0224" />
      <inertia
        ixx="0.0030502"
        ixy="-0.0044343"
        ixz="1.3363E-09"
        iyy="0.017551"
        iyz="9.5786E-10"
        izz="0.019651" />
    </inertial>
    <visual>
      <origin
        xyz="0 0 0"
        rpy="0 0 0" />
      <geometry>
        <mesh
          filename="package://Chassis.SLDASM/meshes/Right Rocker.STL" />
      </geometry>
      <material
        name="">
        <color
          rgba="0.77647 0.75686 0.73725 1" />
      </material>
    </visual>
    <collision>
      <origin
        xyz="0 0 0"
        rpy="0 0 0" />
      <geometry>
        <mesh
          filename="package://Chassis.SLDASM/meshes/Right Rocker.STL" />
      </geometry>
    </collision>
  </link>
  <joint
    name="Rocker Shaft"
    type="continuous">
    <origin
      xyz="-0.249999999999999 -0.231912500000005 0.103175000000004"
      rpy="1.5707963267949 0 3.14159265358979" />
    <parent
      link="base_link" />
    <child
      link="Right Rocker" />
    <axis
      xyz="0 0 1" />
  </joint>
  <link
    name="Right Bogie">
    <inertial>
      <origin
        xyz="0.20548 0.21384 -0.048918"
        rpy="0 0 0" />
      <mass
        value="0.68509" />
      <inertia
        ixx="0.0043847"
        ixy="-0.00095447"
        ixz="-1.8851E-09"
        iyy="0.00065977"
        iyz="2.4989E-09"
        izz="0.0047875" />
    </inertial>
    <visual>
      <origin
        xyz="0 0 0"
        rpy="0 0 0" />
      <geometry>
        <mesh
          filename="package://Chassis.SLDASM/meshes/Right Bogie.STL" />
      </geometry>
      <material
        name="">
        <color
          rgba="0.77647 0.75686 0.73725 1" />
      </material>
    </visual>
    <collision>
      <origin
        xyz="0 0 0"
        rpy="0 0 0" />
      <geometry>
        <mesh
          filename="package://Chassis.SLDASM/meshes/Right Bogie.STL" />
      </geometry>
    </collision>
  </link>
  <joint
    name="Bogie Shaft"
    type="continuous">
    <origin
      xyz="0 0 -0.071072"
      rpy="0 0 -1.334" />
    <parent
      link="Right Rocker" />
    <child
      link="Right Bogie" />
    <axis
      xyz="0 0 1" />
  </joint>
  <link
    name="Left Rocker">
    <inertial>
      <origin
        xyz="-0.0436 -0.043913 0.11068"
        rpy="0 0 0" />
      <mass
        value="1.0224" />
      <inertia
        ixx="0.0030502"
        ixy="-0.0044343"
        ixz="6.7402E-10"
        iyy="0.017551"
        iyz="-1.4767E-09"
        izz="0.019651" />
    </inertial>
    <visual>
      <origin
        xyz="0 0 0"
        rpy="0 0 0" />
      <geometry>
        <mesh
          filename="package://Chassis.SLDASM/meshes/Left Rocker.STL" />
      </geometry>
      <material
        name="">
        <color
          rgba="0.77647 0.75686 0.73725 1" />
      </material>
    </visual>
    <collision>
      <origin
        xyz="0 0 0"
        rpy="0 0 0" />
      <geometry>
        <mesh
          filename="package://Chassis.SLDASM/meshes/Left Rocker.STL" />
      </geometry>
    </collision>
  </link>
  <joint
    name="Left Rocker Shaft"
    type="continuous">
    <origin
      xyz="-0.249999999999993 0.2319125 0.103175"
      rpy="1.5707963267949 0 3.14159265358979" />
    <parent
      link="base_link" />
    <child
      link="Left Rocker" />
    <axis
      xyz="0 0 1" />
  </joint>
  <link
    name="Left Bogie">
    <inertial>
      <origin
        xyz="0.27432 0.11269 0.048918"
        rpy="0 0 0" />
      <mass
        value="0.68509" />
      <inertia
        ixx="0.0030726"
        ixy="-0.0020192"
        ixz="3.1282E-09"
        iyy="0.0019719"
        iyz="1.1064E-10"
        izz="0.0047875" />
    </inertial>
    <visual>
      <origin
        xyz="0 0 0"
        rpy="0 0 0" />
      <geometry>
        <mesh
          filename="package://Chassis.SLDASM/meshes/Left Bogie.STL" />
      </geometry>
      <material
        name="">
        <color
          rgba="0.77647 0.75686 0.73725 1" />
      </material>
    </visual>
    <collision>
      <origin
        xyz="0 0 0"
        rpy="0 0 0" />
      <geometry>
        <mesh
          filename="package://Chassis.SLDASM/meshes/Left Bogie.STL" />
      </geometry>
    </collision>
  </link>
  <joint
    name="Left Bogie Shaft"
    type="continuous">
    <origin
      xyz="0 0 0.071072"
      rpy="0 0 -0.91845" />
    <parent
      link="Left Rocker" />
    <child
      link="Left Bogie" />
    <axis
      xyz="0 0 1" />
  </joint>
  <link
    name="Differential">
    <inertial>
      <origin
        xyz="0.067388 0.00011271 -2.3611E-05"
        rpy="0 0 0" />
      <mass
        value="0.55411" />
      <inertia
        ixx="0.023805"
        ixy="-1.158E-10"
        ixz="-5.0889E-12"
        iyy="0.022506"
        iyz="-0.0051529"
        izz="0.0013117" />
    </inertial>
    <visual>
      <origin
        xyz="0 0 0"
        rpy="0 0 0" />
      <geometry>
        <mesh
          filename="package://Chassis.SLDASM/meshes/Differential.STL" />
      </geometry>
      <material
        name="">
        <color
          rgba="0.79216 0.81961 0.93333 1" />
      </material>
    </visual>
    <collision>
      <origin
        xyz="0 0 0"
        rpy="0 0 0" />
      <geometry>
        <mesh
          filename="package://Chassis.SLDASM/meshes/Differential.STL" />
      </geometry>
    </collision>
  </link>
  <joint
    name="Differential Shaft"
    type="fixed">
    <origin
      xyz="-0.535735000346326 0 0.172959349967733"
      rpy="1.34449872437947 -1.5707963267949 0" />
    <parent
      link="base_link" />
    <child
      link="Differential" />
    <axis
      xyz="0 0 0" />
  </joint>
  <link
    name="Right Link">
    <inertial>
      <origin
        xyz="-5.4049E-07 0.014287 0.14254"
        rpy="0 0 0" />
      <mass
        value="0.053986" />
      <inertia
        ixx="0.00024665"
        ixy="3.9923E-11"
        ixz="1.5169E-11"
        iyy="0.00024666"
        iyz="3.1942E-10"
        izz="7.0552E-07" />
    </inertial>
    <visual>
      <origin
        xyz="0 0 0"
        rpy="0 0 0" />
      <geometry>
        <mesh
          filename="package://Chassis.SLDASM/meshes/Right Link.STL" />
      </geometry>
      <material
        name="">
        <color
          rgba="0.95686 0.95686 0.95686 1" />
      </material>
    </visual>
    <collision>
      <origin
        xyz="0 0 0"
        rpy="0 0 0" />
      <geometry>
        <mesh
          filename="package://Chassis.SLDASM/meshes/Right Link.STL" />
      </geometry>
    </collision>
  </link>
  <joint
    name="Ball Joint"
    type="continuous">
    <origin
      xyz="-0.53574 0.21746 0.375"
      rpy="-1.3176 -0.92154 2.9328" />
    <parent
      link="Differential" />
    <child
      link="Right Link" />
    <axis
      xyz="0 0 0" />
  </joint>
  <link
    name="Left Link">
    <inertial>
      <origin
        xyz="2.83E-07 0.014288 0.14254"
        rpy="0 0 0" />
      <mass
        value="0.053986" />
      <inertia
        ixx="0.00024665"
        ixy="-3.8375E-11"
        ixz="2.4837E-10"
        iyy="0.00024666"
        iyz="-2.3189E-10"
        izz="7.0552E-07" />
    </inertial>
    <visual>
      <origin
        xyz="0 0 0"
        rpy="0 0 0" />
      <geometry>
        <mesh
          filename="package://Chassis.SLDASM/meshes/Left Link.STL" />
      </geometry>
      <material
        name="">
        <color
          rgba="0.95686 0.95686 0.95686 1" />
      </material>
    </visual>
    <collision>
      <origin
        xyz="0 0 0"
        rpy="0 0 0" />
      <geometry>
        <mesh
          filename="package://Chassis.SLDASM/meshes/Left Link.STL" />
      </geometry>
    </collision>
  </link>
  <joint
    name="Left Ball Joint"
    type="fixed">
    <origin
      xyz="-0.535735 0.2174625 -0.375"
      rpy="1.1782 0.68589 -0.26229" />
    <parent
      link="Differential" />
    <child
      link="Left Link" />
    <axis
      xyz="0 0 0" />
  </joint>
</robot>